Workbook

Sheet Cover
A1: Nike, Inc.: Financial Statement Analysis
A2: Five fiscal years, FY2022 to FY2026 (years ending 31 May). Figures in $ millions as reported in Nike's Form 10-K filings.
A4: Purpose | B4: Assess how Nike's growth, profitability, efficiency, liquidity, leverage and cash generation have changed over five years.
A5: Data | B5: Income statement, balance sheet and cash flow statement typed in from the 10-K (FY2021 is used only as the base year for growth and averages).
A6: Method | B6: Common-size statements, trend (growth) analysis, ratio analysis, DuPont breakdown of ROE and a cash flow review.
A8: Sheets
A9: Summary | B9: Key figures and written findings
A10: Charts | B10: Six charts of the main trends
A11: Income Statement / Balance Sheet / Cash Flow | B11: Source statements (blue inputs, black formulas)
A12: Common Size | B12: Each line as a % of revenue or total assets
A13: Ratios | B13: 41 ratios and measures, each with its formula and what it shows
A14: Checks | B14: Model totals reconciled to the 10-K
A16: Colour key
A17: Blue text | B17: Input typed in from the 10-K
A18: Black text | B18: Formula
A19: Green text | B19: Link to another sheet
A21: Checks status | B21: =Checks!B19 -> OK
A22: Sources | B22: NIKE, Inc. Form 10-K, fiscal 2021, 2022, 2023, 2025 and 2026, from SEC EDGAR (sec.gov).

Sheet Summary
A1: Nike: Five-Year Financial Statement Analysis
A2: Key figures, fiscal 2022 to 2026 ($ millions unless stated). All figures link to the statements and ratio sheets.
A4: $ millions unless stated | C4: FY2022 | D4: FY2023 | E4: FY2024 | F4: FY2025 | G4: FY2026 | H4: FY22 to FY26
A5: Revenue | C5: ='Income Statement'!C5 -> 46710 | D5: ='Income Statement'!D5 -> 51217 | E5: ='Income Statement'!E5 -> 51362 | F5: ='Income Statement'!F5 -> 46309 | G5: ='Income Statement'!G5 -> 46398 | H5: =(G5/C5)^(1/4)-1 -> -0.0016740771 | I5: a year (CAGR)
A6: Revenue growth | C6: =Ratios!C6 -> 0.048767345 | D6: =Ratios!D6 -> 0.096488975 | E6: =Ratios!E6 -> 0.0028310912 | F6: =Ratios!F6 -> -0.098380125 | G6: =Ratios!G6 -> 0.0019218726
A7: Gross margin | C7: =Ratios!C12 -> 0.45983729 | D7: =Ratios!D12 -> 0.43524611 | E7: =Ratios!E12 -> 0.44560181 | F7: =Ratios!F12 -> 0.42734674 | G7: =Ratios!G12 -> 0.42913488 | H7: =(G7-C7)*100 -> -3.0702417
A8: Operating (EBIT) margin | C8: =Ratios!C15 -> 0.14290302 | D8: =Ratios!D15 -> 0.115489 | E8: =Ratios!E15 -> 0.12287294 | F8: =Ratios!F15 -> 0.079941264 | G8: =Ratios!G15 -> 0.081835424 | H8: =(G8-C8)*100 -> -6.1067595
A9: Net income | C9: ='Income Statement'!C16 -> 6046 | D9: ='Income Statement'!D16 -> 5070 | E9: ='Income Statement'!E16 -> 5700 | F9: ='Income Statement'!F16 -> 3219 | G9: ='Income Statement'!G16 -> 3108 | H9: =G9/C9-1 -> -0.48594112
A10: Diluted EPS ($) | C10: ='Income Statement'!C18 -> 3.75 | D10: ='Income Statement'!D18 -> 3.23 | E10: ='Income Statement'!E18 -> 3.73 | F10: ='Income Statement'!F18 -> 2.16 | G10: ='Income Statement'!G18 -> 2.1 | H10: =G10/C10-1 -> -0.44
A11: Return on equity | C11: =Ratios!C19 -> 0.43111808 | D11: =Ratios!D19 -> 0.34625235 | E11: =Ratios!E19 -> 0.40092847 | F11: =Ratios!F19 -> 0.23289802 | G11: =Ratios!G19 -> 0.22138329 | H11: =(G11-C11)*100 -> -20.973479
A12: Current ratio | C12: =Ratios!C29 -> 2.6293569 | D12: =Ratios!D29 -> 2.7227744 | E12: =Ratios!E29 -> 2.3961106 | F12: =Ratios!F29 -> 2.2110543 | G12: =Ratios!G29 -> 1.9608671
A13: Cash conversion cycle (days) | C13: =Ratios!C37 -> 101.34884 | D13: =Ratios!D37 -> 98.57022 | E13: =Ratios!E37 -> 96.166058 | F13: =Ratios!F37 -> 95.756526 | G13: =Ratios!G37 -> 96.390564
A14: Net cash (debt) | C14: =Ratios!C44 -> 3567 | D14: =Ratios!D44 -> 1742 | E14: =Ratios!E44 -> 2673 | F14: =Ratios!F44 -> 1185 | G14: =Ratios!G44 -> 1085 | H14: =G14/C14-1 -> -0.69582282
A15: Free cash flow | C15: =Ratios!C52 -> 4430 | D15: =Ratios!D52 -> 4872 | E15: =Ratios!E52 -> 6617 | F15: =Ratios!F52 -> 3268 | G15: =Ratios!G52 -> 2184 | H15: =G15/C15-1 -> -0.50699774
A16: Cash returned to shareholders | C16: =Ratios!C57 -> 5851 | D16: =Ratios!D57 -> 7492 | E16: =Ratios!E57 -> 6419 | F16: =Ratios!F57 -> 5285 | G16: =Ratios!G57 -> 2553
A18: Checks status | C18: =Checks!B19 -> OK
A20: Key findings
A21: 1. Growth has stalled. Revenue rose from $46.7bn (FY2022) to a peak of $51.4bn (FY2024), then fell 9.8% to $46.3bn in FY2025 and was flat at $46.4bn in FY2026.
A22: 2. Profitability has roughly halved. EBIT margin fell from 14.3% to 8.2% and net income from $6.0bn to $3.1bn. Diluted EPS fell from $3.75 to $2.10.
A23: 3. The margin squeeze comes from both lines. Gross margin is down about 3 points (46.0% to 42.9%), and demand creation (marketing) rose from 8.2% to 10.2% of revenue as Nike spent to win back growth.
A24: 4. ROE fell from 43% to 22%. DuPont analysis shows asset turnover and leverage were stable, so the whole decline comes from lower margins.
A25: 5. The balance sheet is still strong but the cushion is thinner. Nike remains net cash ($1.1bn), but down from $3.6bn. The current ratio fell from 2.6x to 2.0x, partly because $2bn of debt falls due within a year.
A26: 6. Cash returns outran cash generation. Over FY2022 to FY2026, Nike returned $27.6bn through buybacks and dividends against $21.4bn of free cash flow. Buybacks were cut to $0.1bn in FY2026, while the dividend kept rising.
A27: 7. Working capital: inventory days are steady at about 103 after the FY2022 glut was cleared, but receivable days rose from 30 to 42, which held back FY2026 cash flow (FCF conversion 70%).
A28: Overall: a financially solid company in a turnaround. The priority to watch is whether gross margin and sales growth recover enough to justify the higher marketing spend.

Sheet Charts
A1: Charts
A2: All charts read from the Ratios and Summary sheets. Fiscal years 2022 to 2026.
A40: Chart data (linked)
A41: Year | B41: FY2022 | C41: FY2023 | D41: FY2024 | E41: FY2025 | F41: FY2026
A42: Revenue | B42: =Summary!C5 -> 46710 | C42: =Summary!D5 -> 51217 | D42: =Summary!E5 -> 51362 | E42: =Summary!F5 -> 46309 | F42: =Summary!G5 -> 46398
A43: Net income | B43: =Summary!C9 -> 6046 | C43: =Summary!D9 -> 5070 | D43: =Summary!E9 -> 5700 | E43: =Summary!F9 -> 3219 | F43: =Summary!G9 -> 3108
A44: Gross margin | B44: =Ratios!C12 -> 0.45983729 | C44: =Ratios!D12 -> 0.43524611 | D44: =Ratios!E12 -> 0.44560181 | E44: =Ratios!F12 -> 0.42734674 | F44: =Ratios!G12 -> 0.42913488
A45: EBIT margin | B45: =Ratios!C15 -> 0.14290302 | C45: =Ratios!D15 -> 0.115489 | D45: =Ratios!E15 -> 0.12287294 | E45: =Ratios!F15 -> 0.079941264 | F45: =Ratios!G15 -> 0.081835424
A46: Net margin | B46: =Ratios!C17 -> 0.12943695 | C46: =Ratios!D17 -> 0.09899057 | D46: =Ratios!E17 -> 0.11097699 | E46: =Ratios!F17 -> 0.069511326 | F46: =Ratios!G17 -> 0.066985646
A47: Free cash flow | B47: =Ratios!C52 -> 4430 | C47: =Ratios!D52 -> 4872 | D47: =Ratios!E52 -> 6617 | E47: =Ratios!F52 -> 3268 | F47: =Ratios!G52 -> 2184
A48: Cash returned | B48: =Ratios!C57 -> 5851 | C48: =Ratios!D57 -> 7492 | D48: =Ratios!E57 -> 6419 | E48: =Ratios!F57 -> 5285 | F48: =Ratios!G57 -> 2553
A49: DSO | B49: =Ratios!C34 -> 35.671698 | C49: =Ratios!D34 -> 31.34965 | D49: =Ratios!E34 -> 30.408376 | E49: =Ratios!F34 -> 36.03576 | F49: =Ratios!G34 -> 41.882409
A50: DIO | B50: =Ratios!C35 -> 110.47937 | C50: =Ratios!D35 -> 106.46517 | D50: =Ratios!E35 -> 102.37305 | E50: =Ratios!F35 -> 103.28293 | F50: =Ratios!G35 -> 103.28369
A51: DPO | B51: =Ratios!C36 -> 44.802227 | C51: =Ratios!D36 -> 39.244598 | D51: =Ratios!E36 -> 36.615364 | E51: =Ratios!F36 -> 43.562163 | F51: =Ratios!G36 -> 48.775531
A52: ROE | B52: =Ratios!C19 -> 0.43111808 | C52: =Ratios!D19 -> 0.34625235 | D52: =Ratios!E19 -> 0.40092847 | E52: =Ratios!F19 -> 0.23289802 | F52: =Ratios!G19 -> 0.22138329
A53: Demand creation % | B53: =Ratios!C13 -> 0.082423464 | C53: =Ratios!D13 -> 0.079270555 | D53: =Ratios!E13 -> 0.083427437 | E53: =Ratios!F13 -> 0.10125462 | F53: =Ratios!G13 -> 0.10246131

Sheet Income Statement
A1: Consolidated Income Statement
A2: Source: NIKE, Inc. Form 10-K filings for fiscal 2021 to 2026 (years end 31 May), as reported.
B3: Base year
A4: $ millions unless stated | B4: FY2021 | C4: FY2022 | D4: FY2023 | E4: FY2024 | F4: FY2025 | G4: FY2026
A5: Revenues | B5: 44538 | C5: 46710 | D5: 51217 | E5: 51362 | F5: 46309 | G5: 46398
A6: Cost of sales | B6: 24576 | C6: 25231 | D6: 28925 | E6: 28475 | F6: 26519 | G6: 26487
A7: Gross profit | B7: =B5-B6 -> 19962 | C7: =C5-C6 -> 21479 | D7: =D5-D6 -> 22292 | E7: =E5-E6 -> 22887 | F7: =F5-F6 -> 19790 | G7: =G5-G6 -> 19911
A8: Demand creation expense | B8: 3114 | C8: 3850 | D8: 4060 | E8: 4285 | F8: 4689 | G8: 4754
A9: Operating overhead expense | B9: 9911 | C9: 10954 | D9: 12317 | E9: 12291 | F9: 11399 | G9: 11360
A10: Total selling and administrative expense | B10: =B8+B9 -> 13025 | C10: =C8+C9 -> 14804 | D10: =D8+D9 -> 16377 | E10: =E8+E9 -> 16576 | F10: =F8+F9 -> 16088 | G10: =G8+G9 -> 16114
A11: Operating income (EBIT) | B11: =B7-B10 -> 6937 | C11: =C7-C10 -> 6675 | D11: =D7-D10 -> 5915 | E11: =E7-E10 -> 6311 | F11: =F7-F10 -> 3702 | G11: =G7-G10 -> 3797
A12: Interest expense (income), net | B12: 262 | C12: 205 | D12: -6 | E12: -161 | F12: -107 | G12: -50
A13: Other (income) expense, net | B13: 14 | C13: -181 | D13: -280 | E13: -228 | F13: -76 | G13: -53
A14: Income before income taxes | B14: =B11-B12-B13 -> 6661 | C14: =C11-C12-C13 -> 6651 | D14: =D11-D12-D13 -> 6201 | E14: =E11-E12-E13 -> 6700 | F14: =F11-F12-F13 -> 3885 | G14: =G11-G12-G13 -> 3900
A15: Income tax expense | B15: 934 | C15: 605 | D15: 1131 | E15: 1000 | F15: 666 | G15: 792
A16: Net income | B16: =B14-B15 -> 5727 | C16: =C14-C15 -> 6046 | D16: =D14-D15 -> 5070 | E16: =E14-E15 -> 5700 | F16: =F14-F15 -> 3219 | G16: =G14-G15 -> 3108
A18: Diluted EPS ($) | B18: 3.56 | C18: 3.75 | D18: 3.23 | E18: 3.73 | F18: 2.16 | G18: 2.1
A19: Diluted weighted average shares (m) | B19: 1609.4 | C19: 1610.8 | D19: 1569.8 | E19: 1529.7 | F19: 1487.6 | G19: 1481

Sheet Balance Sheet
A1: Consolidated Balance Sheet
A2: Source: NIKE, Inc. Form 10-K filings for fiscal 2021 to 2026 (years end 31 May), as reported. Balances at 31 May.
B3: Base year
A4: $ millions unless stated | B4: FY2021 | C4: FY2022 | D4: FY2023 | E4: FY2024 | F4: FY2025 | G4: FY2026
A5: Current assets
A6: Cash and equivalents | B6: 9889 | C6: 8574 | D6: 7441 | E6: 9860 | F6: 7464 | G6: 7563
A7: Short-term investments | B7: 3587 | C7: 4423 | D7: 3234 | E7: 1722 | F7: 1687 | G7: 1464
A8: Accounts receivable, net | B8: 4463 | C8: 4667 | D8: 4131 | E8: 4427 | F8: 4717 | G8: 5931
A9: Inventories | B9: 6854 | C9: 8420 | D9: 8454 | E9: 7519 | F9: 7489 | G9: 7501
A10: Prepaid expenses and other current assets | B10: 1498 | C10: 2129 | D10: 1942 | E10: 1854 | F10: 2005 | G10: 2144
A11: Total current assets | B11: =SUM(B6:B10) -> 26291 | C11: =SUM(C6:C10) -> 28213 | D11: =SUM(D6:D10) -> 25202 | E11: =SUM(E6:E10) -> 25382 | F11: =SUM(F6:F10) -> 23362 | G11: =SUM(G6:G10) -> 24603
A12: Property, plant and equipment, net | B12: 4904 | C12: 4791 | D12: 5081 | E12: 5000 | F12: 4828 | G12: 4796
A13: Operating lease right-of-use assets, net | B13: 3113 | C13: 2926 | D13: 2923 | E13: 2718 | F13: 2712 | G13: 2838
A14: Identifiable intangible assets, net | B14: 269 | C14: 286 | D14: 274 | E14: 259 | F14: 259 | G14: 259
A15: Goodwill | B15: 242 | C15: 284 | D15: 281 | E15: 240 | F15: 240 | G15: 240
A16: Deferred income taxes and other assets | B16: 2921 | C16: 3821 | D16: 3770 | E16: 4511 | F16: 5178 | G16: 5674
A17: Total assets | B17: =B11+B12+B13+B14+B15+B16 -> 37740 | C17: =C11+C12+C13+C14+C15+C16 -> 40321 | D17: =D11+D12+D13+D14+D15+D16 -> 37531 | E17: =E11+E12+E13+E14+E15+E16 -> 38110 | F17: =F11+F12+F13+F14+F15+F16 -> 36579 | G17: =G11+G12+G13+G14+G15+G16 -> 38410
A19: Current liabilities
A20: Current portion of long-term debt | B20: 0 | C20: 500 | D20: 0 | E20: 1000 | F20: 0 | G20: 2000
A21: Notes payable | B21: 2 | C21: 10 | D21: 6 | E21: 6 | F21: 5 | G21: 0
A22: Accounts payable | B22: 2836 | C22: 3358 | D22: 2862 | E22: 2851 | F22: 3479 | G22: 3600
A23: Current portion of operating lease liabilities | B23: 467 | C23: 420 | D23: 425 | E23: 477 | F23: 502 | G23: 478
A24: Accrued liabilities | B24: 6063 | C24: 6220 | D24: 5723 | E24: 5725 | F24: 5911 | G24: 6092
A25: Income taxes payable | B25: 306 | C25: 222 | D25: 240 | E25: 534 | F25: 669 | G25: 377
A26: Total current liabilities | B26: =SUM(B20:B25) -> 9674 | C26: =SUM(C20:C25) -> 10730 | D26: =SUM(D20:D25) -> 9256 | E26: =SUM(E20:E25) -> 10593 | F26: =SUM(F20:F25) -> 10566 | G26: =SUM(G20:G25) -> 12547
A27: Long-term debt | B27: 9413 | C27: 8920 | D27: 8927 | E27: 7903 | F27: 7961 | G27: 5942
A28: Operating lease liabilities | B28: 2931 | C28: 2777 | D28: 2786 | E28: 2566 | F28: 2550 | G28: 2613
A29: Deferred income taxes and other liabilities | B29: 2955 | C29: 2613 | D29: 2558 | E29: 2618 | F29: 2289 | G29: 2443
A30: Total liabilities | B30: =B26+B27+B28+B29 -> 24973 | C30: =C26+C27+C28+C29 -> 25040 | D30: =D26+D27+D28+D29 -> 23527 | E30: =E26+E27+E28+E29 -> 23680 | F30: =F26+F27+F28+F29 -> 23366 | G30: =G26+G27+G28+G29 -> 23545
A32: Shareholders' equity
A33: Common stock at stated value | B33: 3 | C33: 3 | D33: 3 | E33: 3 | F33: 3 | G33: 3
A34: Capital in excess of stated value | B34: 9965 | C34: 11484 | D34: 12412 | E34: 13409 | F34: 14195 | G34: 15158
A35: Accumulated other comprehensive income (loss) | B35: -380 | C35: 318 | D35: 231 | E35: 53 | F35: -258 | G35: -141
A36: Retained earnings (deficit) | B36: 3179 | C36: 3476 | D36: 1358 | E36: 965 | F36: -727 | G36: -155
A37: Total shareholders' equity | B37: =SUM(B33:B36) -> 12767 | C37: =SUM(C33:C36) -> 15281 | D37: =SUM(D33:D36) -> 14004 | E37: =SUM(E33:E36) -> 14430 | F37: =SUM(F33:F36) -> 13213 | G37: =SUM(G33:G36) -> 14865
A38: Total liabilities and shareholders' equity | B38: =B30+B37 -> 37740 | C38: =C30+C37 -> 40321 | D38: =D30+D37 -> 37531 | E38: =E30+E37 -> 38110 | F38: =F30+F37 -> 36579 | G38: =G30+G37 -> 38410

Sheet Cash Flow
A1: Consolidated Cash Flow Statement
A2: Source: NIKE, Inc. Form 10-K filings for fiscal 2021 to 2026 (years end 31 May), as reported.
B3: Base year
A4: $ millions unless stated | B4: FY2021 | C4: FY2022 | D4: FY2023 | E4: FY2024 | F4: FY2025 | G4: FY2026
A5: Operating activities
A6: Net income | B6: ='Income Statement'!B16 -> 5727 | C6: ='Income Statement'!C16 -> 6046 | D6: ='Income Statement'!D16 -> 5070 | E6: ='Income Statement'!E16 -> 5700 | F6: ='Income Statement'!F16 -> 3219 | G6: ='Income Statement'!G16 -> 3108
A7: Depreciation and amortization | B7: 744 | C7: 717 | D7: 703 | E7: 796 | F7: 775 | G7: 747
A8: Deferred income taxes | B8: -385 | C8: -650 | D8: -117 | E8: -497 | F8: -288 | G8: -96
A9: Stock-based compensation | B9: 611 | C9: 638 | D9: 755 | E9: 804 | F9: 709 | G9: 715
A10: Impairment and other | B10: 53 | C10: 123 | D10: 156 | E10: 48 | F10: 33 | G10: 50
A11: Net foreign currency adjustments | B11: -138 | C11: -26 | D11: -213 | E11: -138 | F11: 37 | G11: 22
A12: (Increase) decrease in accounts receivable | B12: -1606 | C12: -504 | D12: 489 | E12: -329 | F12: -257 | G12: -1207
A13: (Increase) decrease in inventories | B13: 507 | C13: -1676 | D13: -133 | E13: 908 | F13: 120 | G13: -31
A14: (Increase) decrease in prepaid expenses and other assets | B14: -182 | C14: -845 | D14: -644 | E14: -260 | F14: -224 | G14: 519
A15: Increase (decrease) in payables and other liabilities | B15: 1326 | C15: 1365 | D15: -225 | E15: 397 | F15: -426 | G15: -959
A16: Cash provided by operations | B16: =SUM(B6:B15) -> 6657 | C16: =SUM(C6:C15) -> 5188 | D16: =SUM(D6:D15) -> 5841 | E16: =SUM(E6:E15) -> 7429 | F16: =SUM(F6:F15) -> 3698 | G16: =SUM(G6:G15) -> 2868
A18: Investing activities
A19: Purchases of short-term investments | B19: -9961 | C19: -12913 | D19: -6059 | E19: -4767 | F19: -3234 | G19: -1316
A20: Maturities of short-term investments | B20: 4236 | C20: 8199 | D20: 3356 | E20: 2269 | F20: 319 | G20: 556
A21: Sales of short-term investments | B21: 2449 | C21: 3967 | D21: 4184 | E21: 4219 | F21: 3062 | G21: 1021
A22: Additions to property, plant and equipment | B22: -695 | C22: -758 | D22: -969 | E22: -812 | F22: -430 | G22: -684
A23: Other investing activities | B23: 171 | C23: -19 | D23: 52 | E23: -15 | F23: 8 | G23: -65
A24: Cash provided (used) by investing activities | B24: =SUM(B19:B23) -> -3800 | C24: =SUM(C19:C23) -> -1524 | D24: =SUM(D19:D23) -> 564 | E24: =SUM(E19:E23) -> 894 | F24: =SUM(F19:F23) -> -275 | G24: =SUM(G19:G23) -> -488
A26: Financing activities
A27: Increase (decrease) in notes payable, net | B27: -52 | C27: 15 | D27: -4 | E27: 0 | F27: -1 | G27: 0
A28: Repayment of borrowings | B28: -197 | C28: 0 | D28: -500 | E28: 0 | F28: -1000 | G28: 0
A29: Proceeds from stock options and other issuances | B29: 1172 | C29: 1151 | D29: 651 | E29: 667 | F29: 551 | G29: 354
A30: Repurchase of common stock | B30: -608 | C30: -4014 | D30: -5480 | E30: -4250 | F30: -2985 | G30: -146
A31: Dividends paid | B31: -1638 | C31: -1837 | D31: -2012 | E31: -2169 | F31: -2300 | G31: -2407
A32: Other financing activities | B32: -136 | C32: -151 | D32: -102 | E32: -136 | F32: -85 | G32: -93
A33: Cash provided (used) by financing activities | B33: =SUM(B27:B32) -> -1459 | C33: =SUM(C27:C32) -> -4836 | D33: =SUM(D27:D32) -> -7447 | E33: =SUM(E27:E32) -> -5888 | F33: =SUM(F27:F32) -> -5820 | G33: =SUM(G27:G32) -> -2292
A35: Effect of exchange rate changes | B35: 143 | C35: -143 | D35: -91 | E35: -16 | F35: 1 | G35: 11
A36: Net increase (decrease) in cash | B36: =B16+B24+B33+B35 -> 1541 | C36: =C16+C24+C33+C35 -> -1315 | D36: =D16+D24+D33+D35 -> -1133 | E36: =E16+E24+E33+E35 -> 2419 | F36: =F16+F24+F33+F35 -> -2396 | G36: =G16+G24+G33+G35 -> 99
A37: Cash at beginning of year | B37: 8348 | C37: =B38 -> 9889 | D37: =C38 -> 8574 | E37: =D38 -> 7441 | F37: =E38 -> 9860 | G37: =F38 -> 7464
A38: Cash at end of year | B38: =B37+B36 -> 9889 | C38: =C37+C36 -> 8574 | D38: =D37+D36 -> 7441 | E38: =E37+E36 -> 9860 | F38: =F37+F36 -> 7464 | G38: =G37+G36 -> 7563
A40: Supplementary disclosure
A41: Cash paid for interest, net of capitalized interest | B41: 293 | C41: 290 | D41: 347 | E41: 381 | F41: 389 | G41: 323

Sheet Common Size
A1: Common-Size Statements
A2: Each line as a % of revenue (income statement) or total assets (balance sheet), so years of different size compare directly.
A4: $ millions unless stated | B4: Formula | C4: FY2022 | D4: FY2023 | E4: FY2024 | F4: FY2025 | G4: FY2026
A5: Income statement, % of revenue
A6: Revenues | B6: Line / revenue | C6: ='Income Statement'!C5/'Income Statement'!C5 -> 1 | D6: ='Income Statement'!D5/'Income Statement'!D5 -> 1 | E6: ='Income Statement'!E5/'Income Statement'!E5 -> 1 | F6: ='Income Statement'!F5/'Income Statement'!F5 -> 1 | G6: ='Income Statement'!G5/'Income Statement'!G5 -> 1
A7: Cost of sales | B7: Line / revenue | C7: ='Income Statement'!C6/'Income Statement'!C5 -> 0.54016271 | D7: ='Income Statement'!D6/'Income Statement'!D5 -> 0.56475389 | E7: ='Income Statement'!E6/'Income Statement'!E5 -> 0.55439819 | F7: ='Income Statement'!F6/'Income Statement'!F5 -> 0.57265326 | G7: ='Income Statement'!G6/'Income Statement'!G5 -> 0.57086512
A8: Gross profit | B8: Line / revenue | C8: ='Income Statement'!C7/'Income Statement'!C5 -> 0.45983729 | D8: ='Income Statement'!D7/'Income Statement'!D5 -> 0.43524611 | E8: ='Income Statement'!E7/'Income Statement'!E5 -> 0.44560181 | F8: ='Income Statement'!F7/'Income Statement'!F5 -> 0.42734674 | G8: ='Income Statement'!G7/'Income Statement'!G5 -> 0.42913488
A9: Demand creation expense | B9: Line / revenue | C9: ='Income Statement'!C8/'Income Statement'!C5 -> 0.082423464 | D9: ='Income Statement'!D8/'Income Statement'!D5 -> 0.079270555 | E9: ='Income Statement'!E8/'Income Statement'!E5 -> 0.083427437 | F9: ='Income Statement'!F8/'Income Statement'!F5 -> 0.10125462 | G9: ='Income Statement'!G8/'Income Statement'!G5 -> 0.10246131
A10: Operating overhead expense | B10: Line / revenue | C10: ='Income Statement'!C9/'Income Statement'!C5 -> 0.23451081 | D10: ='Income Statement'!D9/'Income Statement'!D5 -> 0.24048656 | E10: ='Income Statement'!E9/'Income Statement'!E5 -> 0.23930143 | F10: ='Income Statement'!F9/'Income Statement'!F5 -> 0.24615086 | G10: ='Income Statement'!G9/'Income Statement'!G5 -> 0.24483814
A11: Total selling and administrative expense | B11: Line / revenue | C11: ='Income Statement'!C10/'Income Statement'!C5 -> 0.31693428 | D11: ='Income Statement'!D10/'Income Statement'!D5 -> 0.31975711 | E11: ='Income Statement'!E10/'Income Statement'!E5 -> 0.32272887 | F11: ='Income Statement'!F10/'Income Statement'!F5 -> 0.34740547 | G11: ='Income Statement'!G10/'Income Statement'!G5 -> 0.34729945
A12: Operating income (EBIT) | B12: Line / revenue | C12: ='Income Statement'!C11/'Income Statement'!C5 -> 0.14290302 | D12: ='Income Statement'!D11/'Income Statement'!D5 -> 0.115489 | E12: ='Income Statement'!E11/'Income Statement'!E5 -> 0.12287294 | F12: ='Income Statement'!F11/'Income Statement'!F5 -> 0.079941264 | G12: ='Income Statement'!G11/'Income Statement'!G5 -> 0.081835424
A13: Interest expense (income), net | B13: Line / revenue | C13: ='Income Statement'!C12/'Income Statement'!C5 -> 0.0043887818 | D13: ='Income Statement'!D12/'Income Statement'!D5 -> -0.0001171486 | E13: ='Income Statement'!E12/'Income Statement'!E5 -> -0.0031346131 | F13: ='Income Statement'!F12/'Income Statement'!F5 -> -0.002310566 | G13: ='Income Statement'!G12/'Income Statement'!G5 -> -0.0010776327
A14: Other (income) expense, net | B14: Line / revenue | C14: ='Income Statement'!C13/'Income Statement'!C5 -> -0.0038749732 | D14: ='Income Statement'!D13/'Income Statement'!D5 -> -0.0054669348 | E14: ='Income Statement'!E13/'Income Statement'!E5 -> -0.0044390795 | F14: ='Income Statement'!F13/'Income Statement'!F5 -> -0.0016411497 | G14: ='Income Statement'!G13/'Income Statement'!G5 -> -0.0011422906
A15: Income before income taxes | B15: Line / revenue | C15: ='Income Statement'!C14/'Income Statement'!C5 -> 0.14238921 | D15: ='Income Statement'!D14/'Income Statement'!D5 -> 0.12107308 | E15: ='Income Statement'!E14/'Income Statement'!E5 -> 0.13044663 | F15: ='Income Statement'!F14/'Income Statement'!F5 -> 0.08389298 | G15: ='Income Statement'!G14/'Income Statement'!G5 -> 0.084055347
A16: Income tax expense | B16: Line / revenue | C16: ='Income Statement'!C15/'Income Statement'!C5 -> 0.012952259 | D16: ='Income Statement'!D15/'Income Statement'!D5 -> 0.022082512 | E16: ='Income Statement'!E15/'Income Statement'!E5 -> 0.019469647 | F16: ='Income Statement'!F15/'Income Statement'!F5 -> 0.014381654 | G16: ='Income Statement'!G15/'Income Statement'!G5 -> 0.017069701
A17: Net income | B17: Line / revenue | C17: ='Income Statement'!C16/'Income Statement'!C5 -> 0.12943695 | D17: ='Income Statement'!D16/'Income Statement'!D5 -> 0.09899057 | E17: ='Income Statement'!E16/'Income Statement'!E5 -> 0.11097699 | F17: ='Income Statement'!F16/'Income Statement'!F5 -> 0.069511326 | G17: ='Income Statement'!G16/'Income Statement'!G5 -> 0.066985646
A19: Balance sheet, % of total assets
A20: Cash and equivalents | B20: Line / total assets | C20: ='Balance Sheet'!C6/'Balance Sheet'!C17 -> 0.21264354 | D20: ='Balance Sheet'!D6/'Balance Sheet'!D17 -> 0.19826277 | E20: ='Balance Sheet'!E6/'Balance Sheet'!E17 -> 0.25872474 | F20: ='Balance Sheet'!F6/'Balance Sheet'!F17 -> 0.2040515 | G20: ='Balance Sheet'!G6/'Balance Sheet'!G17 -> 0.19690185
A21: Short-term investments | B21: Line / total assets | C21: ='Balance Sheet'!C7/'Balance Sheet'!C17 -> 0.1096947 | D21: ='Balance Sheet'!D7/'Balance Sheet'!D17 -> 0.086168767 | E21: ='Balance Sheet'!E7/'Balance Sheet'!E17 -> 0.045184991 | F21: ='Balance Sheet'!F7/'Balance Sheet'!F17 -> 0.046119358 | G21: ='Balance Sheet'!G7/'Balance Sheet'!G17 -> 0.038115074
A22: Accounts receivable, net | B22: Line / total assets | C22: ='Balance Sheet'!C8/'Balance Sheet'!C17 -> 0.11574614 | D22: ='Balance Sheet'!D8/'Balance Sheet'!D17 -> 0.11006901 | E22: ='Balance Sheet'!E8/'Balance Sheet'!E17 -> 0.11616374 | F22: ='Balance Sheet'!F8/'Balance Sheet'!F17 -> 0.12895377 | G22: ='Balance Sheet'!G8/'Balance Sheet'!G17 -> 0.15441291
A23: Inventories | B23: Line / total assets | C23: ='Balance Sheet'!C9/'Balance Sheet'!C17 -> 0.20882419 | D23: ='Balance Sheet'!D9/'Balance Sheet'!D17 -> 0.22525379 | E23: ='Balance Sheet'!E9/'Balance Sheet'!E17 -> 0.1972973 | F23: ='Balance Sheet'!F9/'Balance Sheet'!F17 -> 0.20473496 | G23: ='Balance Sheet'!G9/'Balance Sheet'!G17 -> 0.19528769
A24: Prepaid expenses and other current assets | B24: Line / total assets | C24: ='Balance Sheet'!C10/'Balance Sheet'!C17 -> 0.05280127 | D24: ='Balance Sheet'!D10/'Balance Sheet'!D17 -> 0.051743892 | E24: ='Balance Sheet'!E10/'Balance Sheet'!E17 -> 0.048648649 | F24: ='Balance Sheet'!F10/'Balance Sheet'!F17 -> 0.054812871 | G24: ='Balance Sheet'!G10/'Balance Sheet'!G17 -> 0.055818797
A25: Total current assets | B25: Line / total assets | C25: ='Balance Sheet'!C11/'Balance Sheet'!C17 -> 0.69970983 | D25: ='Balance Sheet'!D11/'Balance Sheet'!D17 -> 0.67149823 | E25: ='Balance Sheet'!E11/'Balance Sheet'!E17 -> 0.66601942 | F25: ='Balance Sheet'!F11/'Balance Sheet'!F17 -> 0.63867246 | G25: ='Balance Sheet'!G11/'Balance Sheet'!G17 -> 0.64053632
A26: Property, plant and equipment, net | B26: Line / total assets | C26: ='Balance Sheet'!C12/'Balance Sheet'!C17 -> 0.11882146 | D26: ='Balance Sheet'!D12/'Balance Sheet'!D17 -> 0.13538142 | E26: ='Balance Sheet'!E12/'Balance Sheet'!E17 -> 0.13119916 | F26: ='Balance Sheet'!F12/'Balance Sheet'!F17 -> 0.1319883 | G26: ='Balance Sheet'!G12/'Balance Sheet'!G17 -> 0.12486332
A27: Operating lease right-of-use assets, net | B27: Line / total assets | C27: ='Balance Sheet'!C13/'Balance Sheet'!C17 -> 0.072567645 | D27: ='Balance Sheet'!D13/'Balance Sheet'!D17 -> 0.077882284 | E27: ='Balance Sheet'!E13/'Balance Sheet'!E17 -> 0.071319864 | F27: ='Balance Sheet'!F13/'Balance Sheet'!F17 -> 0.074140901 | G27: ='Balance Sheet'!G13/'Balance Sheet'!G17 -> 0.073887009
A28: Identifiable intangible assets, net | B28: Line / total assets | C28: ='Balance Sheet'!C14/'Balance Sheet'!C17 -> 0.007093078 | D28: ='Balance Sheet'!D14/'Balance Sheet'!D17 -> 0.0073006315 | E28: ='Balance Sheet'!E14/'Balance Sheet'!E17 -> 0.0067961165 | F28: ='Balance Sheet'!F14/'Balance Sheet'!F17 -> 0.0070805654 | G28: ='Balance Sheet'!G14/'Balance Sheet'!G17 -> 0.0067430357
A29: Goodwill | B29: Line / total assets | C29: ='Balance Sheet'!C15/'Balance Sheet'!C17 -> 0.0070434761 | D29: ='Balance Sheet'!D15/'Balance Sheet'!D17 -> 0.007487144 | E29: ='Balance Sheet'!E15/'Balance Sheet'!E17 -> 0.0062975597 | F29: ='Balance Sheet'!F15/'Balance Sheet'!F17 -> 0.0065611416 | G29: ='Balance Sheet'!G15/'Balance Sheet'!G17 -> 0.0062483728
A30: Deferred income taxes and other assets | B30: Line / total assets | C30: ='Balance Sheet'!C16/'Balance Sheet'!C17 -> 0.094764515 | D30: ='Balance Sheet'!D16/'Balance Sheet'!D17 -> 0.10045029 | E30: ='Balance Sheet'!E16/'Balance Sheet'!E17 -> 0.11836788 | F30: ='Balance Sheet'!F16/'Balance Sheet'!F17 -> 0.14155663 | G30: ='Balance Sheet'!G16/'Balance Sheet'!G17 -> 0.14772195
A31: Total assets | B31: Line / total assets | C31: ='Balance Sheet'!C17/'Balance Sheet'!C17 -> 1 | D31: ='Balance Sheet'!D17/'Balance Sheet'!D17 -> 1 | E31: ='Balance Sheet'!E17/'Balance Sheet'!E17 -> 1 | F31: ='Balance Sheet'!F17/'Balance Sheet'!F17 -> 1 | G31: ='Balance Sheet'!G17/'Balance Sheet'!G17 -> 1
A32: Current portion of long-term debt | B32: Line / total assets | C32: ='Balance Sheet'!C20/'Balance Sheet'!C17 -> 0.012400486 | D32: ='Balance Sheet'!D20/'Balance Sheet'!D17 -> 0 | E32: ='Balance Sheet'!E20/'Balance Sheet'!E17 -> 0.026239832 | F32: ='Balance Sheet'!F20/'Balance Sheet'!F17 -> 0 | G32: ='Balance Sheet'!G20/'Balance Sheet'!G17 -> 0.052069773
A33: Notes payable | B33: Line / total assets | C33: ='Balance Sheet'!C21/'Balance Sheet'!C17 -> 0.00024800972 | D33: ='Balance Sheet'!D21/'Balance Sheet'!D17 -> 0.00015986784 | E33: ='Balance Sheet'!E21/'Balance Sheet'!E17 -> 0.00015743899 | F33: ='Balance Sheet'!F21/'Balance Sheet'!F17 -> 0.00013669045 | G33: ='Balance Sheet'!G21/'Balance Sheet'!G17 -> 0
A34: Accounts payable | B34: Line / total assets | C34: ='Balance Sheet'!C22/'Balance Sheet'!C17 -> 0.083281665 | D34: ='Balance Sheet'!D22/'Balance Sheet'!D17 -> 0.076256961 | E34: ='Balance Sheet'!E22/'Balance Sheet'!E17 -> 0.074809761 | F34: ='Balance Sheet'!F22/'Balance Sheet'!F17 -> 0.095109216 | G34: ='Balance Sheet'!G22/'Balance Sheet'!G17 -> 0.093725592
A35: Current portion of operating lease liabilities | B35: Line / total assets | C35: ='Balance Sheet'!C23/'Balance Sheet'!C17 -> 0.010416408 | D35: ='Balance Sheet'!D23/'Balance Sheet'!D17 -> 0.011323972 | E35: ='Balance Sheet'!E23/'Balance Sheet'!E17 -> 0.0125164 | F35: ='Balance Sheet'!F23/'Balance Sheet'!F17 -> 0.013723721 | G35: ='Balance Sheet'!G23/'Balance Sheet'!G17 -> 0.012444676
A36: Accrued liabilities | B36: Line / total assets | C36: ='Balance Sheet'!C24/'Balance Sheet'!C17 -> 0.15426205 | D36: ='Balance Sheet'!D24/'Balance Sheet'!D17 -> 0.15248728 | E36: ='Balance Sheet'!E24/'Balance Sheet'!E17 -> 0.15022304 | F36: ='Balance Sheet'!F24/'Balance Sheet'!F17 -> 0.16159545 | G36: ='Balance Sheet'!G24/'Balance Sheet'!G17 -> 0.15860453
A37: Income taxes payable | B37: Line / total assets | C37: ='Balance Sheet'!C25/'Balance Sheet'!C17 -> 0.0055058158 | D37: ='Balance Sheet'!D25/'Balance Sheet'!D17 -> 0.0063947137 | E37: ='Balance Sheet'!E25/'Balance Sheet'!E17 -> 0.01401207 | F37: ='Balance Sheet'!F25/'Balance Sheet'!F17 -> 0.018289182 | G37: ='Balance Sheet'!G25/'Balance Sheet'!G17 -> 0.0098151523
A38: Total current liabilities | B38: Line / total assets | C38: ='Balance Sheet'!C26/'Balance Sheet'!C17 -> 0.26611443 | D38: ='Balance Sheet'!D26/'Balance Sheet'!D17 -> 0.24662279 | E38: ='Balance Sheet'!E26/'Balance Sheet'!E17 -> 0.27795854 | F38: ='Balance Sheet'!F26/'Balance Sheet'!F17 -> 0.28885426 | G38: ='Balance Sheet'!G26/'Balance Sheet'!G17 -> 0.32665972
A39: Long-term debt | B39: Line / total assets | C39: ='Balance Sheet'!C27/'Balance Sheet'!C17 -> 0.22122467 | D39: ='Balance Sheet'!D27/'Balance Sheet'!D17 -> 0.23785671 | E39: ='Balance Sheet'!E27/'Balance Sheet'!E17 -> 0.20737339 | F39: ='Balance Sheet'!F27/'Balance Sheet'!F17 -> 0.21763854 | G39: ='Balance Sheet'!G27/'Balance Sheet'!G17 -> 0.1546993
A40: Operating lease liabilities | B40: Line / total assets | C40: ='Balance Sheet'!C28/'Balance Sheet'!C17 -> 0.0688723 | D40: ='Balance Sheet'!D28/'Balance Sheet'!D17 -> 0.074231968 | E40: ='Balance Sheet'!E28/'Balance Sheet'!E17 -> 0.067331409 | F40: ='Balance Sheet'!F28/'Balance Sheet'!F17 -> 0.06971213 | G40: ='Balance Sheet'!G28/'Balance Sheet'!G17 -> 0.068029159
A41: Deferred income taxes and other liabilities | B41: Line / total assets | C41: ='Balance Sheet'!C29/'Balance Sheet'!C17 -> 0.06480494 | D41: ='Balance Sheet'!D29/'Balance Sheet'!D17 -> 0.06815699 | E41: ='Balance Sheet'!E29/'Balance Sheet'!E17 -> 0.06869588 | F41: ='Balance Sheet'!F29/'Balance Sheet'!F17 -> 0.062576888 | G41: ='Balance Sheet'!G29/'Balance Sheet'!G17 -> 0.063603228
A42: Total liabilities | B42: Line / total assets | C42: ='Balance Sheet'!C30/'Balance Sheet'!C17 -> 0.62101634 | D42: ='Balance Sheet'!D30/'Balance Sheet'!D17 -> 0.62686846 | E42: ='Balance Sheet'!E30/'Balance Sheet'!E17 -> 0.62135922 | F42: ='Balance Sheet'!F30/'Balance Sheet'!F17 -> 0.63878181 | G42: ='Balance Sheet'!G30/'Balance Sheet'!G17 -> 0.61299141
...

Sheet Ratios
A1: Ratio Analysis
A2: Fiscal years 2022 to 2026. Balance sheet ratios use the average of opening and closing balances.
A4: $ millions unless stated | B4: Formula | C4: FY2022 | D4: FY2023 | E4: FY2024 | F4: FY2025 | G4: FY2026 | H4: What it tells you
A5: Growth
A6: Revenue growth | B6: Revenue / prior year - 1 | C6: ='Income Statement'!C5/'Income Statement'!B5-1 -> 0.048767345 | D6: ='Income Statement'!D5/'Income Statement'!C5-1 -> 0.096488975 | E6: ='Income Statement'!E5/'Income Statement'!D5-1 -> 0.0028310912 | F6: ='Income Statement'!F5/'Income Statement'!E5-1 -> -0.098380125 | G6: ='Income Statement'!G5/'Income Statement'!F5-1 -> 0.0019218726 | H6: Sales peaked in FY2024, then fell almost 10% in FY2025 and were flat in FY2026.
A7: Operating income growth | B7: EBIT / prior year - 1 | C7: ='Income Statement'!C11/'Income Statement'!B11-1 -> -0.037768488 | D7: ='Income Statement'!D11/'Income Statement'!C11-1 -> -0.11385768 | E7: ='Income Statement'!E11/'Income Statement'!D11-1 -> 0.066948436 | F7: ='Income Statement'!F11/'Income Statement'!E11-1 -> -0.41340517 | G7: ='Income Statement'!G11/'Income Statement'!F11-1 -> 0.025661804 | H7: Profit falls much faster than sales: costs did not shrink with revenue (operating leverage).
A8: Net income growth | B8: Net income / prior year - 1 | C8: ='Income Statement'!C16/'Income Statement'!B16-1 -> 0.055701065 | D8: ='Income Statement'!D16/'Income Statement'!C16-1 -> -0.16142904 | E8: ='Income Statement'!E16/'Income Statement'!D16-1 -> 0.12426036 | F8: ='Income Statement'!F16/'Income Statement'!E16-1 -> -0.43526316 | G8: ='Income Statement'!G16/'Income Statement'!F16-1 -> -0.034482759
A9: Diluted EPS growth | B9: EPS / prior year - 1 | C9: ='Income Statement'!C18/'Income Statement'!B18-1 -> 0.053370787 | D9: ='Income Statement'!D18/'Income Statement'!C18-1 -> -0.13866667 | E9: ='Income Statement'!E18/'Income Statement'!D18-1 -> 0.15479876 | F9: ='Income Statement'!F18/'Income Statement'!E18-1 -> -0.42091153 | G9: ='Income Statement'!G18/'Income Statement'!F18-1 -> -0.027777778 | H9: EPS falls slightly less than net income because buybacks reduced the share count.
A11: Profitability
A12: Gross margin | B12: Gross profit / revenue | C12: ='Income Statement'!C7/'Income Statement'!C5 -> 0.45983729 | D12: ='Income Statement'!D7/'Income Statement'!D5 -> 0.43524611 | E12: ='Income Statement'!E7/'Income Statement'!E5 -> 0.44560181 | F12: ='Income Statement'!F7/'Income Statement'!F5 -> 0.42734674 | G12: ='Income Statement'!G7/'Income Statement'!G5 -> 0.42913488 | H12: Down about 3 points from FY2022: heavier discounting to clear inventory and product mix.
A13: Demand creation (marketing) % of revenue | B13: Demand creation / revenue | C13: ='Income Statement'!C8/'Income Statement'!C5 -> 0.082423464 | D13: ='Income Statement'!D8/'Income Statement'!D5 -> 0.079270555 | E13: ='Income Statement'!E8/'Income Statement'!E5 -> 0.083427437 | F13: ='Income Statement'!F8/'Income Statement'!F5 -> 0.10125462 | G13: ='Income Statement'!G8/'Income Statement'!G5 -> 0.10246131 | H13: Marketing spend rose from 8% to over 10% of sales while sales fell.
A14: Operating overhead % of revenue | B14: Operating overhead / revenue | C14: ='Income Statement'!C9/'Income Statement'!C5 -> 0.23451081 | D14: ='Income Statement'!D9/'Income Statement'!D5 -> 0.24048656 | E14: ='Income Statement'!E9/'Income Statement'!E5 -> 0.23930143 | F14: ='Income Statement'!F9/'Income Statement'!F5 -> 0.24615086 | G14: ='Income Statement'!G9/'Income Statement'!G5 -> 0.24483814
A15: Operating (EBIT) margin | B15: EBIT / revenue | C15: ='Income Statement'!C11/'Income Statement'!C5 -> 0.14290302 | D15: ='Income Statement'!D11/'Income Statement'!D5 -> 0.115489 | E15: ='Income Statement'!E11/'Income Statement'!E5 -> 0.12287294 | F15: ='Income Statement'!F11/'Income Statement'!F5 -> 0.079941264 | G15: ='Income Statement'!G11/'Income Statement'!G5 -> 0.081835424 | H15: The key profitability measure: from 14.3% to 8.2% in four years.
A16: EBITDA margin | B16: (EBIT + D&A) / revenue | C16: =('Income Statement'!C11+'Cash Flow'!C7)/'Income Statement'!C5 -> 0.15825305 | D16: =('Income Statement'!D11+'Cash Flow'!D7)/'Income Statement'!D5 -> 0.12921491 | E16: =('Income Statement'!E11+'Cash Flow'!E7)/'Income Statement'!E5 -> 0.13837078 | F16: =('Income Statement'!F11+'Cash Flow'!F7)/'Income Statement'!F5 -> 0.096676672 | G16: =('Income Statement'!G11+'Cash Flow'!G7)/'Income Statement'!G5 -> 0.097935256
A17: Net margin | B17: Net income / revenue | C17: ='Income Statement'!C16/'Income Statement'!C5 -> 0.12943695 | D17: ='Income Statement'!D16/'Income Statement'!D5 -> 0.09899057 | E17: ='Income Statement'!E16/'Income Statement'!E5 -> 0.11097699 | F17: ='Income Statement'!F16/'Income Statement'!F5 -> 0.069511326 | G17: ='Income Statement'!G16/'Income Statement'!G5 -> 0.066985646
A18: Effective tax rate | B18: Tax / profit before tax | C18: ='Income Statement'!C15/'Income Statement'!C14 -> 0.090963765 | D18: ='Income Statement'!D15/'Income Statement'!D14 -> 0.18238994 | E18: ='Income Statement'!E15/'Income Statement'!E14 -> 0.14925373 | F18: ='Income Statement'!F15/'Income Statement'!F14 -> 0.17142857 | G18: ='Income Statement'!G15/'Income Statement'!G14 -> 0.20307692 | H18: Rising tax rate is another drag on net income in FY2026.
A19: Return on equity (ROE) | B19: Net income / average equity | C19: ='Income Statement'!C16/AVERAGE('Balance Sheet'!B37,'Balance Sheet'!C37) -> 0.43111808 | D19: ='Income Statement'!D16/AVERAGE('Balance Sheet'!C37,'Balance Sheet'!D37) -> 0.34625235 | E19: ='Income Statement'!E16/AVERAGE('Balance Sheet'!D37,'Balance Sheet'!E37) -> 0.40092847 | F19: ='Income Statement'!F16/AVERAGE('Balance Sheet'!E37,'Balance Sheet'!F37) -> 0.23289802 | G19: ='Income Statement'!G16/AVERAGE('Balance Sheet'!F37,'Balance Sheet'!G37) -> 0.22138329 | H19: Still high for a consumer company, but roughly halved since FY2022.
A20: Return on assets (ROA) | B20: Net income / average total assets | C20: ='Income Statement'!C16/AVERAGE('Balance Sheet'!B17,'Balance Sheet'!C17) -> 0.1549045 | D20: ='Income Statement'!D16/AVERAGE('Balance Sheet'!C17,'Balance Sheet'!D17) -> 0.13024714 | E20: ='Income Statement'!E16/AVERAGE('Balance Sheet'!D17,'Balance Sheet'!E17) -> 0.15071192 | F20: ='Income Statement'!F16/AVERAGE('Balance Sheet'!E17,'Balance Sheet'!F17) -> 0.086197432 | G20: ='Income Statement'!G16/AVERAGE('Balance Sheet'!F17,'Balance Sheet'!G17) -> 0.082892158
A22: DuPont analysis (ROE = net margin x asset turnover x equity multiplier)
A23: Net margin | B23: Net income / revenue | C23: ='Income Statement'!C16/'Income Statement'!C5 -> 0.12943695 | D23: ='Income Statement'!D16/'Income Statement'!D5 -> 0.09899057 | E23: ='Income Statement'!E16/'Income Statement'!E5 -> 0.11097699 | F23: ='Income Statement'!F16/'Income Statement'!F5 -> 0.069511326 | G23: ='Income Statement'!G16/'Income Statement'!G5 -> 0.066985646 | H23: This is the component that moved: ROE fell because margins fell.
A24: Asset turnover | B24: Revenue / average total assets | C24: ='Income Statement'!C5/AVERAGE('Balance Sheet'!B17,'Balance Sheet'!C17) -> 1.1967564 | D24: ='Income Statement'!D5/AVERAGE('Balance Sheet'!C17,'Balance Sheet'!D17) -> 1.315753 | E24: ='Income Statement'!E5/AVERAGE('Balance Sheet'!D17,'Balance Sheet'!E17) -> 1.3580466 | F24: ='Income Statement'!F5/AVERAGE('Balance Sheet'!E17,'Balance Sheet'!F17) -> 1.2400487 | G24: ='Income Statement'!G5/AVERAGE('Balance Sheet'!F17,'Balance Sheet'!G17) -> 1.2374615 | H24: Stable at about 1.2x to 1.4x.
A25: Equity multiplier | B25: Average assets / average equity | C25: =AVERAGE('Balance Sheet'!B17,'Balance Sheet'!C17)/AVERAGE('Balance Sheet'!B37,'Balance Sheet'!C37) -> 2.7831218 | D25: =AVERAGE('Balance Sheet'!C17,'Balance Sheet'!D17)/AVERAGE('Balance Sheet'!C37,'Balance Sheet'!D37) -> 2.6584258 | E25: =AVERAGE('Balance Sheet'!D17,'Balance Sheet'!E17)/AVERAGE('Balance Sheet'!D37,'Balance Sheet'!E37) -> 2.6602307 | F25: =AVERAGE('Balance Sheet'!E17,'Balance Sheet'!F17)/AVERAGE('Balance Sheet'!E37,'Balance Sheet'!F37) -> 2.7019137 | G25: =AVERAGE('Balance Sheet'!F17,'Balance Sheet'!G17)/AVERAGE('Balance Sheet'!F37,'Balance Sheet'!G37) -> 2.6707387 | H25: Stable leverage, so not the driver.
A26: ROE (DuPont) | B26: Product of the three above | C26: =C23*C24*C25 -> 0.43111808 | D26: =D23*D24*D25 -> 0.34625235 | E26: =E23*E24*E25 -> 0.40092847 | F26: =F23*F24*F25 -> 0.23289802 | G26: =G23*G24*G25 -> 0.22138329 | H26: Equals ROE above: proves the breakdown adds up.
A28: Liquidity
A29: Current ratio | B29: Current assets / current liabilities | C29: ='Balance Sheet'!C11/'Balance Sheet'!C26 -> 2.6293569 | D29: ='Balance Sheet'!D11/'Balance Sheet'!D26 -> 2.7227744 | E29: ='Balance Sheet'!E11/'Balance Sheet'!E26 -> 2.3961106 | F29: ='Balance Sheet'!F11/'Balance Sheet'!F26 -> 2.2110543 | G29: ='Balance Sheet'!G11/'Balance Sheet'!G26 -> 1.9608671 | H29: Comfortable, though down from 2.6x to 2.0x. FY2026 includes $2bn of debt due within a year.
A30: Quick ratio | B30: (Cash + investments + receivables) / current liabilities | C30: =('Balance Sheet'!C6+'Balance Sheet'!C7+'Balance Sheet'!C8)/'Balance Sheet'!C26 -> 1.6462255 | D30: =('Balance Sheet'!D6+'Balance Sheet'!D7+'Balance Sheet'!D8)/'Balance Sheet'!D26 -> 1.5996111 | E30: =('Balance Sheet'!E6+'Balance Sheet'!E7+'Balance Sheet'!E8)/'Balance Sheet'!E26 -> 1.511281 | F30: =('Balance Sheet'!F6+'Balance Sheet'!F7+'Balance Sheet'!F8)/'Balance Sheet'!F26 -> 1.3125118 | G30: =('Balance Sheet'!G6+'Balance Sheet'!G7+'Balance Sheet'!G8)/'Balance Sheet'!G26 -> 1.1921575 | H30: Excludes inventory, which may need discounting to sell.
A31: Cash ratio | B31: (Cash + short-term investments) / current liabilities | C31: =('Balance Sheet'!C6+'Balance Sheet'!C7)/'Balance Sheet'!C26 -> 1.2112768 | D31: =('Balance Sheet'!D6+'Balance Sheet'!D7)/'Balance Sheet'!D26 -> 1.153306 | E31: =('Balance Sheet'!E6+'Balance Sheet'!E7)/'Balance Sheet'!E26 -> 1.0933635 | F31: =('Balance Sheet'!F6+'Balance Sheet'!F7)/'Balance Sheet'!F26 -> 0.86607988 | G31: =('Balance Sheet'!G6+'Balance Sheet'!G7)/'Balance Sheet'!G26 -> 0.71945485
A33: Efficiency (working capital)
A34: Days sales outstanding (DSO) | B34: Average receivables / revenue x 365 | C34: =AVERAGE('Balance Sheet'!B8,'Balance Sheet'!C8)/'Income Statement'!C5*365 -> 35.671698 | D34: =AVERAGE('Balance Sheet'!C8,'Balance Sheet'!D8)/'Income Statement'!D5*365 -> 31.34965 | E34: =AVERAGE('Balance Sheet'!D8,'Balance Sheet'!E8)/'Income Statement'!E5*365 -> 30.408376 | F34: =AVERAGE('Balance Sheet'!E8,'Balance Sheet'!F8)/'Income Statement'!F5*365 -> 36.03576 | G34: =AVERAGE('Balance Sheet'!F8,'Balance Sheet'!G8)/'Income Statement'!G5*365 -> 41.882409 | H34: Customers took about 42 days to pay in FY2026, up from 30: worth watching.
A35: Days inventory outstanding (DIO) | B35: Average inventory / cost of sales x 365 | C35: =AVERAGE('Balance Sheet'!B9,'Balance Sheet'!C9)/'Income Statement'!C6*365 -> 110.47937 | D35: =AVERAGE('Balance Sheet'!C9,'Balance Sheet'!D9)/'Income Statement'!D6*365 -> 106.46517 | E35: =AVERAGE('Balance Sheet'!D9,'Balance Sheet'!E9)/'Income Statement'!E6*365 -> 102.37305 | F35: =AVERAGE('Balance Sheet'!E9,'Balance Sheet'!F9)/'Income Statement'!F6*365 -> 103.28293 | G35: =AVERAGE('Balance Sheet'!F9,'Balance Sheet'!G9)/'Income Statement'!G6*365 -> 103.28369 | H35: Inventory was cut back after the FY2022 glut and is now steady.
A36: Days payables outstanding (DPO) | B36: Average payables / cost of sales x 365 | C36: =AVERAGE('Balance Sheet'!B22,'Balance Sheet'!C22)/'Income Statement'!C6*365 -> 44.802227 | D36: =AVERAGE('Balance Sheet'!C22,'Balance Sheet'!D22)/'Income Statement'!D6*365 -> 39.244598 | E36: =AVERAGE('Balance Sheet'!D22,'Balance Sheet'!E22)/'Income Statement'!E6*365 -> 36.615364 | F36: =AVERAGE('Balance Sheet'!E22,'Balance Sheet'!F22)/'Income Statement'!F6*365 -> 43.562163 | G36: =AVERAGE('Balance Sheet'!F22,'Balance Sheet'!G22)/'Income Statement'!G6*365 -> 48.775531
A37: Cash conversion cycle | B37: DSO + DIO - DPO | C37: =C34+C35-C36 -> 101.34884 | D37: =D34+D35-D36 -> 98.57022 | E37: =E34+E35-E36 -> 96.166058 | F37: =F34+F35-F36 -> 95.756526 | G37: =G34+G35-G36 -> 96.390564 | H37: Days of sales tied up in working capital. Slightly better than FY2022.
A38: Inventory turnover | B38: Cost of sales / average inventory | C38: ='Income Statement'!C6/AVERAGE('Balance Sheet'!B9,'Balance Sheet'!C9) -> 3.3037842 | D38: ='Income Statement'!D6/AVERAGE('Balance Sheet'!C9,'Balance Sheet'!D9) -> 3.4283513 | E38: ='Income Statement'!E6/AVERAGE('Balance Sheet'!D9,'Balance Sheet'!E9) -> 3.5653916 | F38: ='Income Statement'!F6/AVERAGE('Balance Sheet'!E9,'Balance Sheet'!F9) -> 3.5339819 | G38: ='Income Statement'!G6/AVERAGE('Balance Sheet'!F9,'Balance Sheet'!G9) -> 3.533956
A39: Asset turnover | B39: Revenue / average total assets | C39: ='Income Statement'!C5/AVERAGE('Balance Sheet'!B17,'Balance Sheet'!C17) -> 1.1967564 | D39: ='Income Statement'!D5/AVERAGE('Balance Sheet'!C17,'Balance Sheet'!D17) -> 1.315753 | E39: ='Income Statement'!E5/AVERAGE('Balance Sheet'!D17,'Balance Sheet'!E17) -> 1.3580466 | F39: ='Income Statement'!F5/AVERAGE('Balance Sheet'!E17,'Balance Sheet'!F17) -> 1.2400487 | G39: ='Income Statement'!G5/AVERAGE('Balance Sheet'!F17,'Balance Sheet'!G17) -> 1.2374615
A41: Leverage and solvency
A42: Total debt | B42: Current + long-term debt + notes payable | C42: ='Balance Sheet'!C20+'Balance Sheet'!C21+'Balance Sheet'!C27 -> 9430 | D42: ='Balance Sheet'!D20+'Balance Sheet'!D21+'Balance Sheet'!D27 -> 8933 | E42: ='Balance Sheet'!E20+'Balance Sheet'!E21+'Balance Sheet'!E27 -> 8909 | F42: ='Balance Sheet'!F20+'Balance Sheet'!F21+'Balance Sheet'!F27 -> 7966 | G42: ='Balance Sheet'!G20+'Balance Sheet'!G21+'Balance Sheet'!G27 -> 7942 | H42: Excludes lease liabilities.
A43: Cash and short-term investments | C43: ='Balance Sheet'!C6+'Balance Sheet'!C7 -> 12997 | D43: ='Balance Sheet'!D6+'Balance Sheet'!D7 -> 10675 | E43: ='Balance Sheet'!E6+'Balance Sheet'!E7 -> 11582 | F43: ='Balance Sheet'!F6+'Balance Sheet'!F7 -> 9151 | G43: ='Balance Sheet'!G6+'Balance Sheet'!G7 -> 9027
A44: Net cash (debt) | B44: Cash and investments - total debt | C44: =C43-C42 -> 3567 | D44: =D43-D42 -> 1742 | E44: =E43-E42 -> 2673 | F44: =F43-F42 -> 1185 | G44: =G43-G42 -> 1085 | H44: Still net cash, but the cushion shrank from $3.6bn to $1.1bn.
A45: Debt to equity | B45: Total debt / equity | C45: =C42/'Balance Sheet'!C37 -> 0.61710621 | D45: =D42/'Balance Sheet'!D37 -> 0.63788917 | E45: =E42/'Balance Sheet'!E37 -> 0.61739432 | F45: =F42/'Balance Sheet'!F37 -> 0.60289109 | G45: =G42/'Balance Sheet'!G37 -> 0.53427514
A46: Debt to EBITDA | B46: Total debt / EBITDA | C46: =C42/('Income Statement'!C11+'Cash Flow'!C7) -> 1.2757035 | D46: =D42/('Income Statement'!D11+'Cash Flow'!D7) -> 1.3498036 | E46: =E42/('Income Statement'!E11+'Cash Flow'!E7) -> 1.2535528 | F46: =F42/('Income Statement'!F11+'Cash Flow'!F7) -> 1.7793165 | G46: =G42/('Income Statement'!G11+'Cash Flow'!G7) -> 1.7477993 | H46: Rose from 1.3x to 1.7x because EBITDA fell, not because debt rose.
...

Sheet Checks
A1: Checks
A2: Every check should show OK. Reported totals are typed in from the 10-K and compared with the totals the model calculates.
A4: $ millions unless stated | B4: FY2021 | C4: FY2022 | D4: FY2023 | E4: FY2024 | F4: FY2025 | G4: FY2026
A5: Gross profit agrees to 10-K (difference) | B5: =ROUND('Income Statement'!B7-19962,0) -> 0 | C5: =ROUND('Income Statement'!C7-21479,0) -> 0 | D5: =ROUND('Income Statement'!D7-22292,0) -> 0 | E5: =ROUND('Income Statement'!E7-22887,0) -> 0 | F5: =ROUND('Income Statement'!F7-19790,0) -> 0 | G5: =ROUND('Income Statement'!G7-19911,0) -> 0
A6: Income before taxes agrees to 10-K (difference) | B6: =ROUND('Income Statement'!B14-6661,0) -> 0 | C6: =ROUND('Income Statement'!C14-6651,0) -> 0 | D6: =ROUND('Income Statement'!D14-6201,0) -> 0 | E6: =ROUND('Income Statement'!E14-6700,0) -> 0 | F6: =ROUND('Income Statement'!F14-3885,0) -> 0 | G6: =ROUND('Income Statement'!G14-3900,0) -> 0
A7: Net income agrees to 10-K (difference) | B7: =ROUND('Income Statement'!B16-5727,0) -> 0 | C7: =ROUND('Income Statement'!C16-6046,0) -> 0 | D7: =ROUND('Income Statement'!D16-5070,0) -> 0 | E7: =ROUND('Income Statement'!E16-5700,0) -> 0 | F7: =ROUND('Income Statement'!F16-3219,0) -> 0 | G7: =ROUND('Income Statement'!G16-3108,0) -> 0
A8: Total current assets agree to 10-K (difference) | B8: =ROUND('Balance Sheet'!B11-26291,0) -> 0 | C8: =ROUND('Balance Sheet'!C11-28213,0) -> 0 | D8: =ROUND('Balance Sheet'!D11-25202,0) -> 0 | E8: =ROUND('Balance Sheet'!E11-25382,0) -> 0 | F8: =ROUND('Balance Sheet'!F11-23362,0) -> 0 | G8: =ROUND('Balance Sheet'!G11-24603,0) -> 0
A9: Total assets agree to 10-K (difference) | B9: =ROUND('Balance Sheet'!B17-37740,0) -> 0 | C9: =ROUND('Balance Sheet'!C17-40321,0) -> 0 | D9: =ROUND('Balance Sheet'!D17-37531,0) -> 0 | E9: =ROUND('Balance Sheet'!E17-38110,0) -> 0 | F9: =ROUND('Balance Sheet'!F17-36579,0) -> 0 | G9: =ROUND('Balance Sheet'!G17-38410,0) -> 0
A10: Total current liabilities agree to 10-K (difference) | B10: =ROUND('Balance Sheet'!B26-9674,0) -> 0 | C10: =ROUND('Balance Sheet'!C26-10730,0) -> 0 | D10: =ROUND('Balance Sheet'!D26-9256,0) -> 0 | E10: =ROUND('Balance Sheet'!E26-10593,0) -> 0 | F10: =ROUND('Balance Sheet'!F26-10566,0) -> 0 | G10: =ROUND('Balance Sheet'!G26-12547,0) -> 0
A11: Total equity agrees to 10-K (difference) | B11: =ROUND('Balance Sheet'!B37-12767,0) -> 0 | C11: =ROUND('Balance Sheet'!C37-15281,0) -> 0 | D11: =ROUND('Balance Sheet'!D37-14004,0) -> 0 | E11: =ROUND('Balance Sheet'!E37-14430,0) -> 0 | F11: =ROUND('Balance Sheet'!F37-13213,0) -> 0 | G11: =ROUND('Balance Sheet'!G37-14865,0) -> 0
A12: Cash from operations agrees to 10-K (difference) | B12: =ROUND('Cash Flow'!B16-6657,0) -> 0 | C12: =ROUND('Cash Flow'!C16-5188,0) -> 0 | D12: =ROUND('Cash Flow'!D16-5841,0) -> 0 | E12: =ROUND('Cash Flow'!E16-7429,0) -> 0 | F12: =ROUND('Cash Flow'!F16-3698,0) -> 0 | G12: =ROUND('Cash Flow'!G16-2868,0) -> 0
A13: Cash from investing agrees to 10-K (difference) | B13: =ROUND('Cash Flow'!B24--3800,0) -> 0 | C13: =ROUND('Cash Flow'!C24--1524,0) -> 0 | D13: =ROUND('Cash Flow'!D24-564,0) -> 0 | E13: =ROUND('Cash Flow'!E24-894,0) -> 0 | F13: =ROUND('Cash Flow'!F24--275,0) -> 0 | G13: =ROUND('Cash Flow'!G24--488,0) -> 0
A14: Cash from financing agrees to 10-K (difference) | B14: =ROUND('Cash Flow'!B33--1459,0) -> 0 | C14: =ROUND('Cash Flow'!C33--4836,0) -> 0 | D14: =ROUND('Cash Flow'!D33--7447,0) -> 0 | E14: =ROUND('Cash Flow'!E33--5888,0) -> 0 | F14: =ROUND('Cash Flow'!F33--5820,0) -> 0 | G14: =ROUND('Cash Flow'!G33--2292,0) -> 0
A15: Balance sheet balances (assets - liabilities - equity) | B15: =ROUND('Balance Sheet'!B17-'Balance Sheet'!B38,0) -> 0 | C15: =ROUND('Balance Sheet'!C17-'Balance Sheet'!C38,0) -> 0 | D15: =ROUND('Balance Sheet'!D17-'Balance Sheet'!D38,0) -> 0 | E15: =ROUND('Balance Sheet'!E17-'Balance Sheet'!E38,0) -> 0 | F15: =ROUND('Balance Sheet'!F17-'Balance Sheet'!F38,0) -> 0 | G15: =ROUND('Balance Sheet'!G17-'Balance Sheet'!G38,0) -> 0
A16: Cash flow ending cash = balance sheet cash | B16: =ROUND('Cash Flow'!B38-'Balance Sheet'!B6,0) -> 0 | C16: =ROUND('Cash Flow'!C38-'Balance Sheet'!C6,0) -> 0 | D16: =ROUND('Cash Flow'!D38-'Balance Sheet'!D6,0) -> 0 | E16: =ROUND('Cash Flow'!E38-'Balance Sheet'!E6,0) -> 0 | F16: =ROUND('Cash Flow'!F38-'Balance Sheet'!F6,0) -> 0 | G16: =ROUND('Cash Flow'!G38-'Balance Sheet'!G6,0) -> 0
A17: Diluted EPS ties to net income / shares (cents) | B17: =ROUND(('Income Statement'!B16/'Income Statement'!B19-'Income Statement'!B18)*100,0) -> 0 | C17: =ROUND(('Income Statement'!C16/'Income Statement'!C19-'Income Statement'!C18)*100,0) -> 0 | D17: =ROUND(('Income Statement'!D16/'Income Statement'!D19-'Income Statement'!D18)*100,0) -> 0 | E17: =ROUND(('Income Statement'!E16/'Income Statement'!E19-'Income Statement'!E18)*100,0) -> 0 | F17: =ROUND(('Income Statement'!F16/'Income Statement'!F19-'Income Statement'!F18)*100,0) -> 0 | G17: =ROUND(('Income Statement'!G16/'Income Statement'!G19-'Income Statement'!G18)*100,0) -> 0
A19: Overall status | B19: =IF(SUMPRODUCT(ABS(B5:G17))=0,"OK","ERROR") -> OK
